Workbook
Name Lim_BP_DiaHigh: '⚙ Dashboard Settings'!$I$11
Name Lim_BP_SysHigh: '⚙ Dashboard Settings'!$I$9
Name Lim_BP_SysLow: '⚙ Dashboard Settings'!$I$10
Name Lim_Sugar_Alert: '⚙ Dashboard Settings'!$I$7
Name VisitDateList: '🗓 Doctor Visit Log'!$V$6:INDEX('🗓 Doctor Visit Log'!$V$6:$V$117,MAX(1,COUNT('🗓 Doctor Visit Log'!$V$6:$V$117)))

Sheet 📋 How To Print
B2: NEPHRO HEALTHCARE TRACKER ( PERSONAL ) - Ver 2.0
B3: Read all Instructions very carefully before commencing Data Entry in any Datasheet
B5: Record Vitals at Home → Update Lab Reports { prior to each Consultation / Doctor's visit / Before Every Follow-up | E5: Send by E-Mail prior to your Follow-up / Carry along Prints of the Doctor Pack (Doctor Referral Report + Dashboard + Daily Vitals Log)
B6: YOUR VITALS DATA ROUTINE — 5 SIMPLE STEPS | E6: DOCTOR PACK ( 3 SHEETS, ABOUT 6 PAGES ) : E-MAIL / BE CARRIED FOR CONSULTATIONS
B7: 1 | C7: Once: Fill 👤 Patient Info (yellow cells). Every other sheet reads from it. | E7: Send or carry only these three sheets. In a 10–15 minute consultation the doctor needs a clear summary first, with the day-by-day readings behind it.
B9: 2 | C9: Every day: Record / enter BP, Pulse, SpO₂, Weight, Fluids and Sugar (FBS) in 📅 Daily Vitals Log. | E9: 🩺 Doctor Referral Report (1 page) — who you are, last-7-day vitals, latest labs, current medicines, space for the doctor's plan.
B11: 3 | C11: At Each Lab test / Visit: Type the test date in row 4 of 🧪 Lab Results (oldest first, left to right, no empty column), then the results below it in relevant cells. | E11: 📈 Dashboard (2 pages) — alerts, creatinine / eGFR / tacrolimus trends, lab snapshot, home BP, weight, urine, SpO₂ and sugar trends.
B13: 4 | C13: When New Medicines are Added / Medicines Change: Add a new line (For New Meds) in 💊 Medication History and set Status = ACTIVE. If dosage of a particular medicine is Incr / Decr, mark it as CHANGED and put the Date of change at relevant place (column J ). Add a fresh Medication Entry [With Revised Data] in a Blank New Row and set its Status = ACTIVE. Add a remark suitably in " Clinical Notes / Remarks" Column. | E13: 📅 Daily Vitals Log (about 3 pages) — every day's BP, pulse, SpO₂, weight, fluids, urine and sugar, for the doctor to study in detail.
B17: 5 | C17: Before each visit: check 🩺 Doctor Referral Report, 📈 Dashboard and 📅 Daily Vitals Log, then send by E-Mail / Carry along : the Doctor Pack (see right). | E17: DOCTOR PACK : OPTION 1 — SAVE AS PDF (RECOMMENDED)
E18: 1 | F18: Click the 🩺 Doctor Referral Report tab, hold Ctrl and click the 📈 Dashboard and 📅 Daily Vitals Log tabs — all three are now selected.
B20: COLOUR CODES IN USE | E20: 2 | F20: Press Ctrl+P (Windows) or Cmd+P (Mac). Printer: Microsoft Print to PDF (Windows) or Save as PDF (Mac).
C21: Yellow cell = you type here
C22: White / grey cell = works itself out — please don't overwrite | E22: 3 | F22: Under Settings choose Print Active Sheets — not Print Entire Workbook.
C23: Red / orange = outside the safe limit — INFORM your doctor
E24: 4 | F24: Click Print / Save and name the file, e.g. PatientName_Doctor_Pack_05Oct2026.pdf.
B25: BEFORE EVERY CONSULTATION APPOINTMENT / VISIT — CHECKLIST
B26: ☐ Daily Vitals Log is filled in and is up to today | E26: 5 | F26: Email or WhatsApp the PDF to your doctor before the visit. Then click any other tab to un-select the sheets.
B27: ☐ Latest lab results have been entered, dates oldest → newest
B28: ☐ Medication History is up to date
B29: ☐ Dashboard Layout and Doctor Referral Report look right | E29: DOCTOR PACK : OPTION 2 — PRINT ON PAPER
B30: ☐ Dated copy of this file saved (e.g. Nephro_Tracker_05Oct2026.xlsx) | E30: ▶ | F30: Select the same three tabs → Ctrl+P → Print Active Sheets → choose printer → Print. Carry the pages to the clinic.
B32: WHAT EACH SHEET CONTAINS (colour = tab colour, ★ = goes to the doctor)
C33: 📋 How To Print → This guide | E33: ONLY IF THE DOCTOR ASKS — KEEP READY, DON'T SEND ROUTINELY
B34: ★ | C34: 🩺 Doctor Referral Report → 1-page summary for the doctor | E34: 🧪 Lab Results — the full table, to compare older tests
B35: ★ | C35: 📈 Dashboard → Alerts, lab snapshot, 8 trend charts | E35: 💊 Medication History — to review past dose changes
C36: 👤 Patient Info → Demographics, transplant details, history | E36: 📊 Weekly Summary — week-by-week averages (1 page)
B37: ★ | C37: 📅 Daily Vitals Log → BP, pulse, SpO₂, weight, fluids, sugar | E37: Original hospital lab reports — the official record (Always better to Carry along during consultation visits)
C38: 🧪 Lab Results → All blood & urine tests across dates
C39: 💊 Medication History → Medicine log: start, stop, changes
C40: 🗓 Doctor Visit Log → Date of consultation + key values per visit | E40: PLEASE DON'T SEND THE ENTIRE WORKBOOK [ By E-mail / Whatsapp ]
C41: 📊 Weekly Summary → Weekly averages + alert counts | E41: Sending every sheet adds 8+ more pages of raw tables (patient info, lab table, medication log, visit log, settings). They bury the key findings, use up the doctor's limited time, and share more personal data than needed. Keep the full file for your own records.
C42: 📖 Lab Reference Ranges → Post-transplant targets
C43: ⚙ Dashboard Settings → Alert limits you can edit

Sheet 👤 Patient Info
B1: NEPHROLOGY FOLLOW-UP TRACKER
B2: Patient Information Sheet | Complete once — all other sheets reference this page
B3: Treating Nephrologist:
B4: Doctor Name: | E4: Doctor Phone:
B5: Hospital / Clinic: | E5: Doctor Email:
B6: Reg. No.: | E6: Website:
B7: PATIENT DETAILS
B8: Patient Name: | E8: Patient ID / MRD No.:
B9: Date of Birth: | E9: Referring Doctor:
B10: Age (years): | E10: Diagnosis:
B11: Gender: | E11: Transplant Date:
B12: Blood Group: | E12: Donor Type:
B13: Contact No.:
B14: TRANSPLANT & MEDICAL HISTORY
B15: Primary Kidney Disease:
B16: Dialysis History (from – to):
B17: Known Allergies:
B18: Comorbidities:
B19: Current Immunosuppression Regimen: | C19: As per Medication History sheet
B20: Other Medications: | C20: As per Medication History sheet
B21: NOTES / CLINICIAN INSTRUCTIONS

Sheet 📅 Daily Vitals Log
B1: DAILY HOME MONITORING LOG — KIDNEY TRANSPLANT PATIENT
B2: Fill every day at the SAME time. Yellow cells = mandatory. Alert doctor immediately for RED values. Bring this log to every visit.
B3: Date | C3: BP Systolic (mmHg) | D3: BP Diastolic (mmHg) | E3: Pulse (bpm) | F3: SpO₂ (%) | G3: Temp (°F) | H3: Weight (kg) | I3: Fluid In (mL) | J3: Urine Out (mL) | K3: Urine Freq (#/day) | L3: Oedema? (Y/N) | M3: Blood Sugar (mg/dL) | N3: Meds Taken? | O3: Symptoms / Notes | P3: BP Alert | Q3: SpO₂ Alert
P4: =IF(OR(C4="",D4=""),"",IF(OR(C4>'⚙ Dashboard Settings'!$I$9,C4<'⚙ Dashboard Settings'!$I$10,D4>'⚙ Dashboard Settings'!$I$11),"⚠ ALERT","OK")) | Q4: =IF(F4="","",IF(F4<94,"🚨 LOW","OK"))
P5: =IF(OR(C5="",D5=""),"",IF(OR(C5>'⚙ Dashboard Settings'!$I$9,C5<'⚙ Dashboard Settings'!$I$10,D5>'⚙ Dashboard Settings'!$I$11),"⚠ ALERT","OK")) | Q5: =IF(F5="","",IF(F5<94,"🚨 LOW","OK"))
P6: =IF(OR(C6="",D6=""),"",IF(OR(C6>'⚙ Dashboard Settings'!$I$9,C6<'⚙ Dashboard Settings'!$I$10,D6>'⚙ Dashboard Settings'!$I$11),"⚠ ALERT","OK")) | Q6: =IF(F6="","",IF(F6<94,"🚨 LOW","OK"))
P7: =IF(OR(C7="",D7=""),"",IF(OR(C7>'⚙ Dashboard Settings'!$I$9,C7<'⚙ Dashboard Settings'!$I$10,D7>'⚙ Dashboard Settings'!$I$11),"⚠ ALERT","OK")) | Q7: =IF(F7="","",IF(F7<94,"🚨 LOW","OK"))
P8: =IF(OR(C8="",D8=""),"",IF(OR(C8>'⚙ Dashboard Settings'!$I$9,C8<'⚙ Dashboard Settings'!$I$10,D8>'⚙ Dashboard Settings'!$I$11),"⚠ ALERT","OK")) | Q8: =IF(F8="","",IF(F8<94,"🚨 LOW","OK"))
P9: =IF(OR(C9="",D9=""),"",IF(OR(C9>'⚙ Dashboard Settings'!$I$9,C9<'⚙ Dashboard Settings'!$I$10,D9>'⚙ Dashboard Settings'!$I$11),"⚠ ALERT","OK")) | Q9: =IF(F9="","",IF(F9<94,"🚨 LOW","OK"))
P10: =IF(OR(C10="",D10=""),"",IF(OR(C10>'⚙ Dashboard Settings'!$I$9,C10<'⚙ Dashboard Settings'!$I$10,D10>'⚙ Dashboard Settings'!$I$11),"⚠ ALERT","OK")) | Q10: =IF(F10="","",IF(F10<94,"🚨 LOW","OK"))
P11: =IF(OR(C11="",D11=""),"",IF(OR(C11>'⚙ Dashboard Settings'!$I$9,C11<'⚙ Dashboard Settings'!$I$10,D11>'⚙ Dashboard Settings'!$I$11),"⚠ ALERT","OK")) | Q11: =IF(F11="","",IF(F11<94,"🚨 LOW","OK"))
P12: =IF(OR(C12="",D12=""),"",IF(OR(C12>'⚙ Dashboard Settings'!$I$9,C12<'⚙ Dashboard Settings'!$I$10,D12>'⚙ Dashboard Settings'!$I$11),"⚠ ALERT","OK")) | Q12: =IF(F12="","",IF(F12<94,"🚨 LOW","OK"))
P13: =IF(OR(C13="",D13=""),"",IF(OR(C13>'⚙ Dashboard Settings'!$I$9,C13<'⚙ Dashboard Settings'!$I$10,D13>'⚙ Dashboard Settings'!$I$11),"⚠ ALERT","OK")) | Q13: =IF(F13="","",IF(F13<94,"🚨 LOW","OK"))
P14: =IF(OR(C14="",D14=""),"",IF(OR(C14>'⚙ Dashboard Settings'!$I$9,C14<'⚙ Dashboard Settings'!$I$10,D14>'⚙ Dashboard Settings'!$I$11),"⚠ ALERT","OK")) | Q14: =IF(F14="","",IF(F14<94,"🚨 LOW","OK"))
P15: =IF(OR(C15="",D15=""),"",IF(OR(C15>'⚙ Dashboard Settings'!$I$9,C15<'⚙ Dashboard Settings'!$I$10,D15>'⚙ Dashboard Settings'!$I$11),"⚠ ALERT","OK")) | Q15: =IF(F15="","",IF(F15<94,"🚨 LOW","OK"))
... P113: =IF(OR(C113="",D113=""),"",IF(OR(C113>'⚙ Dashboard Settings'!$I$9,C113<'⚙ Dashboard Settings'!$I$10,D113>'⚙ Dashboard Settings'!$I$11),"⚠ ALERT","OK")) | Q113: =IF(F113="","",IF(F113<94,"🚨 LOW","OK"))
B115: COLOUR LEGEND: 🟡 Yellow = Mandatory entry | 🔴 Red BP = outside the BP limits in ⚙ Dashboard Settings (default: Systolic >140 or <90, Diastolic >90) | 🚨 Red SpO₂ = <94% (call doctor) | 🟠 Orange Sugar = above alert limit in ⚙ Dashboard Settings (default >180 mg/dL) | * Blood Sugar = fasting value before breakfast | Fluid In = all liquids consumed | Urine Out = total 24-hr collection

Sheet 🧪 Lab Results
B1: BLOOD & URINE TEST LOG — SERIAL LAB RESULTS
B2: HOW TO ENTER: type each test date in row 4 (DATE →), moving LEFT → RIGHT and OLDEST FIRST, with no empty column in between (out-of-order dates are blocked). Then enter that visit's results below; leave a result blank if it was not tested. 🟢 = Normal 🟡 = Borderline 🔴 = Out of Range
B3: Test / Parameter | C3: Unit | D3: Normal Range (General) | E3: TX Target (Post-Tx) | F3: Frequency | G3: Test Date 1 (enter date →) | H3: Test Date 2 (enter date →) | I3: Test Date 3 (enter date →) | J3: Test Date 4 (enter date →) | K3: Test Date 5 (enter date →) | L3: Test Date 6 (enter date →) | M3: Test Date 7 (enter date →) | N3: Test Date 8 (enter date →) | O3: Test Date 9 (enter date →) | P3: Test Date 10 (enter date →) | Q3: Test Date 11 (enter date →) | R3: Test Date 12 (enter date →) | S3: Test Date 13 (enter date →) | T3: Test Date 14 (enter date →) | U3: Test Date 15 (enter date →) | V3: Test Date 16 (enter date →) | W3: Test Date 17 (enter date →) | X3: Test Date 18 (enter date →) | Y3: Test Date 19 (enter date →) | Z3: Test Date 20 (enter date →)
B4: DATE →
B5: RENAL FUNCTION
B6: Serum Creatinine | C6: mg/dL | D6: 0.6 – 1.2 | E6: Stable baseline | F6: Monthly
B7: eGFR | C7: mL/min | D7: ≥ 60 | E7: ≥ 45 | F7: Monthly
B8: Tacrolimus Trough | C8: ng/mL | D8: — | E8: Early: 8–12 | Late: 5–8 | F8: Monthly
B9: ELECTROLYTES
B10: Calcium (Total) | C10: mg/dL | D10: 8.5 – 10.5 | E10: 8.5 – 10.2 | F10: Monthly
B11: Phosphorus | C11: mg/dL | D11: 2.5 – 4.5 | E11: 2.5 – 4.5 | F11: Monthly
B12: Uric Acid | C12: mg/dL | D12: 2.4 – 7.0 | E12: < 7.0 | F12: Monthly
B13: Potassium | C13: mEq/L | D13: 3.5 – 5.0 | E13: 3.5 – 5.0 | F13: Monthly
B14: Sodium | C14: mEq/L | D14: 135 – 145 | E14: 135 – 145 | F14: Monthly
B15: Serum Bicarbonate | C15: mEq/L | D15: 22 – 29 | E15: 22 – 29 | F15: Monthly
B16: METABOLIC / GLUCOSE
B17: FBS (Fasting Sugar) | C17: mg/dL | D17: 70 – 100 | E17: 70 – 126 | F17: Monthly
B18: PPBS (Post-meal) | C18: mg/dL | D18: ≤ 140 | E18: ≤ 180 | F18: Monthly
B19: HbA1c | C19: % | D19: ≤ 5.7 | E19: ≤ 7.0 | F19: 3-Monthly
B20: COMPLETE BLOOD COUNT
B21: Haemoglobin | C21: g/dL | D21: 12 – 17 | E21: 11 – 14 | F21: Monthly
B22: TLC (WBC) | C22: ×10³/μL | D22: 4 – 11 | E22: 4 – 10 | F22: Monthly
B23: Platelets | C23: ×10³/μL | D23: 150 – 400 | E23: 150 – 350 | F23: Monthly
B24: LIVER & METABOLIC
B25: Serum Albumin | C25: g/dL | D25: 3.5 – 5.0 | E25: 3.5 – 5.0 | F25: Monthly
B26: Total Bilirubin | C26: mg/dL | D26: ≤ 1.2 | E26: ≤ 1.2 | F26: 3-Monthly
B27: SGOT / AST | C27: U/L | D27: ≤ 40 | E27: ≤ 40 | F27: 3-Monthly
B28: SGPT / ALT | C28: U/L | D28: ≤ 56 | E28: ≤ 56 | F28: 3-Monthly
B29: Lipid Profile (LDL) | C29: mg/dL | D29: ≤ 100 | E29: ≤ 100 | F29: 3-Monthly
B30: IMMUNOSUPPRESSION MONITORING
B31: Vitamin D (25-OH) | C31: ng/mL | D31: 30 – 100 | E31: 30 – 100 | F31: 3-Monthly
B32: BKV PCR | C32: copies/mL | D32: Negative | E32: < 10,000 | F32: Monthly × 9m then 3m
B33: CMV PCR | C33: copies/mL | D33: Negative | E33: Undetectable | F33: Monthly × 6m
B34: URINE TESTS
B35: Urine RE (Protein) | C35: – | D35: — | E35: Nil / Trace | F35: Monthly
B36: Urine RE (RBC/WBC) | C36: cells/hpf | D36: ≤ 5 | E36: ≤ 5 | F36: Monthly
B37: Urine C/S | C37: – | D37: — | E37: No Growth | F37: If symptomatic
B38: Urine PCR (UACR) | C38: mg/g | D38: < 150 | E38: < 300 | F38: Monthly
B39: 24h Urine Protein | C39: mg/24h | D39: < 150 | E39: < 300 | F39: If indicated
B40: DOCTOR'S NOTES ON LATEST RESULTS

Sheet 💊 Medication History
B1: MEDICATION HISTORY — UNIFIED LOG (Current Medications + All Changes)
B2: Add a new row for every medication added, changed, or stopped. Status: ACTIVE | CHANGED | STOPPED
B3: Last Prescription Date: | H3: Prescribing Doctor:
B4: Brand Name | C4: Composition / Generic | D4: Category | E4: Dose | F4: Timing & Frequency | G4: Route | H4: Start Date | I4: Status | J4: Stop Date | K4: Clinical Notes / Remarks

Sheet 📈 Dashboard
B1: CLINICAL TRENDS DASHBOARD — AUTO-GENERATED FROM DAILY VITALS & LAB RESULTS
B2: Charts auto-update when data is entered in Daily Vitals Log and Lab Results sheets. Review trends at each visit.
B3: ⚠ AUTOMATIC CLINICAL ALERTS ⚠
B4: Latest BP: | C4: =IF(COUNT('📅 Daily Vitals Log'!C4:C113)=0,"ℹ No BP readings entered yet",IF(OR(LOOKUP(2,1/('📅 Daily Vitals Log'!C4:C113<>""),'📅 Daily Vitals Log'!C4:C113)>'⚙ Dashboard Settings'!$I$9,IFERROR(LOOKUP(2,1/('📅 Daily Vitals Log'!D4:D113<>""),'📅 Daily Vitals Log'!D4:D113),0)>'⚙ Dashboard Settings'!$I$11),"🚨 HIGH BP: "&LOOKUP(2,1/('📅 Daily Vitals Log'!C4:C113<>""),'📅 Daily Vitals Log'!C4:C113)&" / "&IFERROR(LOOKUP(2,1/('📅 Daily Vitals Log'!D4:D113<>""),'📅 Daily Vitals Log'!D4:D113),"?")&" mmHg — Contact doctor",IF(LOOKUP(2,1/('📅 Daily Vitals Log'!C4:C113<>""),'📅 Daily Vitals Log'!C4:C113)<'⚙ Dashboard Settings'!$I$10,"🚨 LOW BP: "&LOOKUP(2,1/('📅 Daily Vitals Log'!C4:C113<>""),'📅 Daily Vitals Log'!C4:C113)&" / "&IFERROR(LOOKUP(2,1/('📅 Daily Vitals Log'!D4:D113<>""),'📅 Daily Vitals Log'!D4:D113),"?")&" mmHg — Contact doctor","✅ BP OK"))) -> ℹ No BP readings entered yet
B5: Latest SpO₂: | C5: =IF(COUNT('📅 Daily Vitals Log'!F4:F113)=0,"ℹ No SpO₂ readings entered yet",IF(LOOKUP(2,1/('📅 Daily Vitals Log'!F4:F113<>""),'📅 Daily Vitals Log'!F4:F113)<94,"🚨 LOW SpO₂: "&LOOKUP(2,1/('📅 Daily Vitals Log'!F4:F113<>""),'📅 Daily Vitals Log'!F4:F113)&"% — URGENT","✅ SpO₂ OK")) -> ℹ No SpO₂ readings entered yet
B6: Latest Blood Sugar: | C6: =IF(COUNT('📅 Daily Vitals Log'!M4:M113)=0,"ℹ No blood sugar readings entered yet",IF(LOOKUP(2,1/('📅 Daily Vitals Log'!M4:M113<>""),'📅 Daily Vitals Log'!M4:M113)>'⚙ Dashboard Settings'!$I$7,"⚠ HIGH GLUCOSE: "&LOOKUP(2,1/('📅 Daily Vitals Log'!M4:M113<>""),'📅 Daily Vitals Log'!M4:M113)&" mg/dL","✅ Glucose OK")) -> ℹ No blood sugar readings entered yet
B7: Weight 7d change: | C7: =IFERROR(IF(LOOKUP(2,1/('📅 Daily Vitals Log'!H4:H113<>""),'📅 Daily Vitals Log'!H4:H113)-IFERROR(AVERAGEIFS('📅 Daily Vitals Log'!H:H,'📅 Daily Vitals Log'!B:B,">="&(LOOKUP(2,1/('📅 Daily Vitals Log'!B4:B113<>""),'📅 Daily Vitals Log'!B4:B113)-7),'📅 Daily Vitals Log'!B:B,"<="&(LOOKUP(2,1/('📅 Daily Vitals Log'!B4:B113<>""),'📅 Daily Vitals Log'!B4:B113)-1)),LOOKUP(2,1/('📅 Daily Vitals Log'!H4:H113<>""),'📅 Daily Vitals Log'!H4:H113))>2,"⚠ WEIGHT GAIN +"&TEXT(LOOKUP(2,1/('📅 Daily Vitals Log'!H4:H113<>""),'📅 Daily Vitals Log'!H4:H113)-IFERROR(AVERAGEIFS('📅 Daily Vitals Log'!H:H,'📅 Daily Vitals Log'!B:B,">="&(LOOKUP(2,1/('📅 Daily Vitals Log'!B4:B113<>""),'📅 Daily Vitals Log'!B4:B113)-7),'📅 Daily Vitals Log'!B:B,"<="&(LOOKUP(2,1/('📅 Daily Vitals Log'!B4:B113<>""),'📅 Daily Vitals Log'!B4:B113)-1)),LOOKUP(2,1/('📅 Daily Vitals Log'!H4:H113<>""),'📅 Daily Vitals Log'!H4:H113)),"0.00")&" kg vs prior 7d avg","✅ Weight stable (latest: "&TEXT(LOOKUP(2,1/('📅 Daily Vitals Log'!H4:H113<>""),'📅 Daily Vitals Log'!H4:H113),"0.00")&" kg)"),"—") -> —
B8: Latest Creatinine: | C8: =IF(COUNT('🧪 Lab Results'!G6:Z6)=0,"ℹ No creatinine result entered yet",IF(LOOKUP(2,1/('🧪 Lab Results'!G6:Z6<>""),'🧪 Lab Results'!G6:Z6)>'⚙ Dashboard Settings'!$I$13,"⚠ HIGH CREATININE: "&LOOKUP(2,1/('🧪 Lab Results'!G6:Z6<>""),'🧪 Lab Results'!G6:Z6)&" mg/dL — Review urgently",IF(LOOKUP(2,1/('🧪 Lab Results'!G6:Z6<>""),'🧪 Lab Results'!G6:Z6)>'⚙ Dashboard Settings'!$I$12,"⚠ Borderline Creatinine: "&LOOKUP(2,1/('🧪 Lab Results'!G6:Z6<>""),'🧪 Lab Results'!G6:Z6)&" mg/dL","✅ Creatinine OK"))) -> ℹ No creatinine result entered yet
B9: Latest Tacrolimus: | C9: =IF(COUNT('🧪 Lab Results'!G8:Z8)=0,"ℹ No tacrolimus level entered yet",IF(LOOKUP(2,1/('🧪 Lab Results'!G8:Z8<>""),'🧪 Lab Results'!G8:Z8)<'⚙ Dashboard Settings'!$D$8,"⚠ TAC LOW: "&LOOKUP(2,1/('🧪 Lab Results'!G8:Z8<>""),'🧪 Lab Results'!G8:Z8)&" ng/mL — Sub-therapeutic",IF(LOOKUP(2,1/('🧪 Lab Results'!G8:Z8<>""),'🧪 Lab Results'!G8:Z8)>'⚙ Dashboard Settings'!$E$8,"⚠ TAC HIGH: "&LOOKUP(2,1/('🧪 Lab Results'!G8:Z8<>""),'🧪 Lab Results'!G8:Z8)&" ng/mL — Toxicity risk","✅ Tac level OK"))) -> ℹ No tacrolimus level entered yet
B10: Labs out of range: | C10: =IF(SUMPRODUCT(--('⚙ Dashboard Settings'!$M$6:$M$28>0))=0,"ℹ No lab results entered yet",IF(SUMPRODUCT(--(LEN('⚙ Dashboard Settings'!$L$6:$L$28)>0))=0,"✅ All "&SUMPRODUCT(--('⚙ Dashboard Settings'!$M$6:$M$28>0))&" recorded lab parameters are within your set limits","⚠ "&SUMPRODUCT(--(LEN('⚙ Dashboard Settings'!$L$6:$L$28)>0))&" of "&SUMPRODUCT(--('⚙ Dashboard Settings'!$M$6:$M$28>0))&" recorded lab parameters outside limits: "&'⚙ Dashboard Settings'!$O$28)) -> ℹ No lab results entered yet
B12: 📈 KIDNEY GRAFT & DRUG-LEVEL TRENDS — Creatinine · eGFR · Tacrolimus trough (auto-plotted from 🧪 Lab Results)
B55: 🧪 LAB SNAPSHOT — latest result vs previous, checked against your set limits
B56: ="Latest lab date on file: "&IF(MAX('🧪 Lab Results'!$G$4:$Z$4)=0,"—",TEXT(MAX('🧪 Lab Results'!$G$4:$Z$4),"dd-mmm-yyyy"))&" | Parameters with results: "&SUMPRODUCT(--('⚙ Dashboard Settings'!$M$6:$M$28>0))&" of "&ROWS('⚙ Dashboard Settings'!$M$6:$M$28)&" | Outside limits: "&SUMPRODUCT(--(LEN('⚙ Dashboard Settings'!$L$6:$L$28)>0)) -> Latest lab date on file: — | Parameters with results: 0 of 23 | Outside limits: 0
B57: Parameter | E57: Unit | F57: Latest | G57: Date | H57: Previous | I57: Change | J57: Trend | K57: Normal range | M57: Post-Tx target | O57: Status | P57: Readings | Q57: Frequency
B58: =TRIM('🧪 Lab Results'!$B$6) -> Serum Creatinine | E58: =IF('🧪 Lab Results'!$C$6="","",'🧪 Lab Results'!$C$6) -> mg/dL | F58: =IF('⚙ Dashboard Settings'!$M$6=0,"—",INDEX('🧪 Lab Results'!$G6:$Z6,'⚙ Dashboard Settings'!$M$6-6)) -> — | G58: =IF('⚙ Dashboard Settings'!$M$6=0,"—",IF(INDEX('🧪 Lab Results'!$G$4:$Z$4,'⚙ Dashboard Settings'!$M$6-6)="","no date",INDEX('🧪 Lab Results'!$G$4:$Z$4,'⚙ Dashboard Settings'!$M$6-6))) -> — | H58: =IF('⚙ Dashboard Settings'!$N$6=0,"—",INDEX('🧪 Lab Results'!$G6:$Z6,'⚙ Dashboard Settings'!$N$6-6)) -> — | I58: =IF(AND(ISNUMBER(F58),ISNUMBER(H58)),ROUND(F58-H58,3),"—") -> — | J58: =IF(NOT(ISNUMBER(I58)),"—",IF(H58=0,IF(I58=0,"● Stable",IF(I58>0,"▲ Rising","▼ Falling")),IF(ABS(I58)/ABS(H58)*100<'⚙ Dashboard Settings'!$I$8,"● Stable",IF(I58>0,"▲ Rising","▼ Falling")))) -> — | K58: =IF('🧪 Lab Results'!$D$6="","",'🧪 Lab Results'!$D$6) -> 0.6 – 1.2 | M58: =IF('🧪 Lab Results'!$E$6="","",'🧪 Lab Results'!$E$6) -> Stable baseline | O58: =IF(OR('⚙ Dashboard Settings'!$M$6=0,NOT(ISNUMBER(F58))),"—",IF(AND(ISNUMBER('⚙ Dashboard Settings'!$D$6),F58<'⚙ Dashboard Settings'!$D$6),"▼ LOW",IF(AND(ISNUMBER('⚙ Dashboard Settings'!$E$6),F58>'⚙ Dashboard Settings'!$E$6),"▲ HIGH",IF(AND(NOT(ISNUMBER('⚙ Dashboard Settings'!$D$6)),NOT(ISNUMBER('⚙ Dashboard Settings'!$E$6))),"—","✔ In range")))) -> — | P58: =COUNT('🧪 Lab Results'!$G6:$Z6) -> 0 | Q58: =IF('🧪 Lab Results'!$F$6="","",'🧪 Lab Results'!$F$6) -> Monthly
B59: =TRIM('🧪 Lab Results'!$B$7) -> eGFR | E59: =IF('🧪 Lab Results'!$C$7="","",'🧪 Lab Results'!$C$7) -> mL/min | F59: =IF('⚙ Dashboard Settings'!$M$7=0,"—",INDEX('🧪 Lab Results'!$G7:$Z7,'⚙ Dashboard Settings'!$M$7-6)) -> — | G59: =IF('⚙ Dashboard Settings'!$M$7=0,"—",IF(INDEX('🧪 Lab Results'!$G$4:$Z$4,'⚙ Dashboard Settings'!$M$7-6)="","no date",INDEX('🧪 Lab Results'!$G$4:$Z$4,'⚙ Dashboard Settings'!$M$7-6))) -> — | H59: =IF('⚙ Dashboard Settings'!$N$7=0,"—",INDEX('🧪 Lab Results'!$G7:$Z7,'⚙ Dashboard Settings'!$N$7-6)) -> — | I59: =IF(AND(ISNUMBER(F59),ISNUMBER(H59)),ROUND(F59-H59,3),"—") -> — | J59: =IF(NOT(ISNUMBER(I59)),"—",IF(H59=0,IF(I59=0,"● Stable",IF(I59>0,"▲ Rising","▼ Falling")),IF(ABS(I59)/ABS(H59)*100<'⚙ Dashboard Settings'!$I$8,"● Stable",IF(I59>0,"▲ Rising","▼ Falling")))) -> — | K59: =IF('🧪 Lab Results'!$D$7="","",'🧪 Lab Results'!$D$7) -> ≥ 60 | M59: =IF('🧪 Lab Results'!$E$7="","",'🧪 Lab Results'!$E$7) -> ≥ 45 | O59: =IF(OR('⚙ Dashboard Settings'!$M$7=0,NOT(ISNUMBER(F59))),"—",IF(AND(ISNUMBER('⚙ Dashboard Settings'!$D$7),F59<'⚙ Dashboard Settings'!$D$7),"▼ LOW",IF(AND(ISNUMBER('⚙ Dashboard Settings'!$E$7),F59>'⚙ Dashboard Settings'!$E$7),"▲ HIGH",IF(AND(NOT(ISNUMBER('⚙ Dashboard Settings'!$D$7)),NOT(ISNUMBER('⚙ Dashboard Settings'!$E$7))),"—","✔ In range")))) -> — | P59: =COUNT('🧪 Lab Results'!$G7:$Z7) -> 0 | Q59: =IF('🧪 Lab Results'!$F$7="","",'🧪 Lab Results'!$F$7) -> Monthly
B60: =TRIM('🧪 Lab Results'!$B$8) -> Tacrolimus Trough | E60: =IF('🧪 Lab Results'!$C$8="","",'🧪 Lab Results'!$C$8) -> ng/mL | F60: =IF('⚙ Dashboard Settings'!$M$8=0,"—",INDEX('🧪 Lab Results'!$G8:$Z8,'⚙ Dashboard Settings'!$M$8-6)) -> — | G60: =IF('⚙ Dashboard Settings'!$M$8=0,"—",IF(INDEX('🧪 Lab Results'!$G$4:$Z$4,'⚙ Dashboard Settings'!$M$8-6)="","no date",INDEX('🧪 Lab Results'!$G$4:$Z$4,'⚙ Dashboard Settings'!$M$8-6))) -> — | H60: =IF('⚙ Dashboard Settings'!$N$8=0,"—",INDEX('🧪 Lab Results'!$G8:$Z8,'⚙ Dashboard Settings'!$N$8-6)) -> — | I60: =IF(AND(ISNUMBER(F60),ISNUMBER(H60)),ROUND(F60-H60,3),"—") -> — | J60: =IF(NOT(ISNUMBER(I60)),"—",IF(H60=0,IF(I60=0,"● Stable",IF(I60>0,"▲ Rising","▼ Falling")),IF(ABS(I60)/ABS(H60)*100<'⚙ Dashboard Settings'!$I$8,"● Stable",IF(I60>0,"▲ Rising","▼ Falling")))) -> — | K60: =IF('🧪 Lab Results'!$D$8="","",'🧪 Lab Results'!$D$8) -> — | M60: =IF('🧪 Lab Results'!$E$8="","",'🧪 Lab Results'!$E$8) -> Early: 8–12 | Late: 5–8 | O60: =IF(OR('⚙ Dashboard Settings'!$M$8=0,NOT(ISNUMBER(F60))),"—",IF(AND(ISNUMBER('⚙ Dashboard Settings'!$D$8),F60<'⚙ Dashboard Settings'!$D$8),"▼ LOW",IF(AND(ISNUMBER('⚙ Dashboard Settings'!$E$8),F60>'⚙ Dashboard Settings'!$E$8),"▲ HIGH",IF(AND(NOT(ISNUMBER('⚙ Dashboard Settings'!$D$8)),NOT(ISNUMBER('⚙ Dashboard Settings'!$E$8))),"—","✔ In range")))) -> — | P60: =COUNT('🧪 Lab Results'!$G8:$Z8) -> 0 | Q60: =IF('🧪 Lab Results'!$F$8="","",'🧪 Lab Results'!$F$8) -> Monthly
B61: =TRIM('🧪 Lab Results'!$B$10) -> Calcium (Total) | E61: =IF('🧪 Lab Results'!$C$10="","",'🧪 Lab Results'!$C$10) -> mg/dL | F61: =IF('⚙ Dashboard Settings'!$M$9=0,"—",INDEX('🧪 Lab Results'!$G10:$Z10,'⚙ Dashboard Settings'!$M$9-6)) -> — | G61: =IF('⚙ Dashboard Settings'!$M$9=0,"—",IF(INDEX('🧪 Lab Results'!$G$4:$Z$4,'⚙ Dashboard Settings'!$M$9-6)="","no date",INDEX('🧪 Lab Results'!$G$4:$Z$4,'⚙ Dashboard Settings'!$M$9-6))) -> — | H61: =IF('⚙ Dashboard Settings'!$N$9=0,"—",INDEX('🧪 Lab Results'!$G10:$Z10,'⚙ Dashboard Settings'!$N$9-6)) -> — | I61: =IF(AND(ISNUMBER(F61),ISNUMBER(H61)),ROUND(F61-H61,3),"—") -> — | J61: =IF(NOT(ISNUMBER(I61)),"—",IF(H61=0,IF(I61=0,"● Stable",IF(I61>0,"▲ Rising","▼ Falling")),IF(ABS(I61)/ABS(H61)*100<'⚙ Dashboard Settings'!$I$8,"● Stable",IF(I61>0,"▲ Rising","▼ Falling")))) -> — | K61: =IF('🧪 Lab Results'!$D$10="","",'🧪 Lab Results'!$D$10) -> 8.5 – 10.5 | M61: =IF('🧪 Lab Results'!$E$10="","",'🧪 Lab Results'!$E$10) -> 8.5 – 10.2 | O61: =IF(OR('⚙ Dashboard Settings'!$M$9=0,NOT(ISNUMBER(F61))),"—",IF(AND(ISNUMBER('⚙ Dashboard Settings'!$D$9),F61<'⚙ Dashboard Settings'!$D$9),"▼ LOW",IF(AND(ISNUMBER('⚙ Dashboard Settings'!$E$9),F61>'⚙ Dashboard Settings'!$E$9),"▲ HIGH",IF(AND(NOT(ISNUMBER('⚙ Dashboard Settings'!$D$9)),NOT(ISNUMBER('⚙ Dashboard Settings'!$E$9))),"—","✔ In range")))) -> — | P61: =COUNT('🧪 Lab Results'!$G10:$Z10) -> 0 | Q61: =IF('🧪 Lab Results'!$F$10="","",'🧪 Lab Results'!$F$10) -> Monthly
B62: =TRIM('🧪 Lab Results'!$B$11) -> Phosphorus | E62: =IF('🧪 Lab Results'!$C$11="","",'🧪 Lab Results'!$C$11) -> mg/dL | F62: =IF('⚙ Dashboard Settings'!$M$10=0,"—",INDEX('🧪 Lab Results'!$G11:$Z11,'⚙ Dashboard Settings'!$M$10-6)) -> — | G62: =IF('⚙ Dashboard Settings'!$M$10=0,"—",IF(INDEX('🧪 Lab Results'!$G$4:$Z$4,'⚙ Dashboard Settings'!$M$10-6)="","no date",INDEX('🧪 Lab Results'!$G$4:$Z$4,'⚙ Dashboard Settings'!$M$10-6))) -> — | H62: =IF('⚙ Dashboard Settings'!$N$10=0,"—",INDEX('🧪 Lab Results'!$G11:$Z11,'⚙ Dashboard Settings'!$N$10-6)) -> — | I62: =IF(AND(ISNUMBER(F62),ISNUMBER(H62)),ROUND(F62-H62,3),"—") -> — | J62: =IF(NOT(ISNUMBER(I62)),"—",IF(H62=0,IF(I62=0,"● Stable",IF(I62>0,"▲ Rising","▼ Falling")),IF(ABS(I62)/ABS(H62)*100<'⚙ Dashboard Settings'!$I$8,"● Stable",IF(I62>0,"▲ Rising","▼ Falling")))) -> — | K62: =IF('🧪 Lab Results'!$D$11="","",'🧪 Lab Results'!$D$11) -> 2.5 – 4.5 | M62: =IF('🧪 Lab Results'!$E$11="","",'🧪 Lab Results'!$E$11) -> 2.5 – 4.5 | O62: =IF(OR('⚙ Dashboard Settings'!$M$10=0,NOT(ISNUMBER(F62))),"—",IF(AND(ISNUMBER('⚙ Dashboard Settings'!$D$10),F62<'⚙ Dashboard Settings'!$D$10),"▼ LOW",IF(AND(ISNUMBER('⚙ Dashboard Settings'!$E$10),F62>'⚙ Dashboard Settings'!$E$10),"▲ HIGH",IF(AND(NOT(ISNUMBER('⚙ Dashboard Settings'!$D$10)),NOT(ISNUMBER('⚙ Dashboard Settings'!$E$10))),"—","✔ In range")))) -> — | P62: =COUNT('🧪 Lab Results'!$G11:$Z11) -> 0 | Q62: =IF('🧪 Lab Results'!$F$11="","",'🧪 Lab Results'!$F$11) -> Monthly
B63: =TRIM('🧪 Lab Results'!$B$12) -> Uric Acid | E63: =IF('🧪 Lab Results'!$C$12="","",'🧪 Lab Results'!$C$12) -> mg/dL | F63: =IF('⚙ Dashboard Settings'!$M$11=0,"—",INDEX('🧪 Lab Results'!$G12:$Z12,'⚙ Dashboard Settings'!$M$11-6)) -> — | G63: =IF('⚙ Dashboard Settings'!$M$11=0,"—",IF(INDEX('🧪 Lab Results'!$G$4:$Z$4,'⚙ Dashboard Settings'!$M$11-6)="","no date",INDEX('🧪 Lab Results'!$G$4:$Z$4,'⚙ Dashboard Settings'!$M$11-6))) -> — | H63: =IF('⚙ Dashboard Settings'!$N$11=0,"—",INDEX('🧪 Lab Results'!$G12:$Z12,'⚙ Dashboard Settings'!$N$11-6)) -> — | I63: =IF(AND(ISNUMBER(F63),ISNUMBER(H63)),ROUND(F63-H63,3),"—") -> — | J63: =IF(NOT(ISNUMBER(I63)),"—",IF(H63=0,IF(I63=0,"● Stable",IF(I63>0,"▲ Rising","▼ Falling")),IF(ABS(I63)/ABS(H63)*100<'⚙ Dashboard Settings'!$I$8,"● Stable",IF(I63>0,"▲ Rising","▼ Falling")))) -> — | K63: =IF('🧪 Lab Results'!$D$12="","",'🧪 Lab Results'!$D$12) -> 2.4 – 7.0 | M63: =IF('🧪 Lab Results'!$E$12="","",'🧪 Lab Results'!$E$12) -> < 7.0 | O63: =IF(OR('⚙ Dashboard Settings'!$M$11=0,NOT(ISNUMBER(F63))),"—",IF(AND(ISNUMBER('⚙ Dashboard Settings'!$D$11),F63<'⚙ Dashboard Settings'!$D$11),"▼ LOW",IF(AND(ISNUMBER('⚙ Dashboard Settings'!$E$11),F63>'⚙ Dashboard Settings'!$E$11),"▲ HIGH",IF(AND(NOT(ISNUMBER('⚙ Dashboard Settings'!$D$11)),NOT(ISNUMBER('⚙ Dashboard Settings'!$E$11))),"—","✔ In range")))) -> — | P63: =COUNT('🧪 Lab Results'!$G12:$Z12) -> 0 | Q63: =IF('🧪 Lab Results'!$F$12="","",'🧪 Lab Results'!$F$12) -> Monthly
B64: =TRIM('🧪 Lab Results'!$B$13) -> Potassium | E64: =IF('🧪 Lab Results'!$C$13="","",'🧪 Lab Results'!$C$13) -> mEq/L | F64: =IF('⚙ Dashboard Settings'!$M$12=0,"—",INDEX('🧪 Lab Results'!$G13:$Z13,'⚙ Dashboard Settings'!$M$12-6)) -> — | G64: =IF('⚙ Dashboard Settings'!$M$12=0,"—",IF(INDEX('🧪 Lab Results'!$G$4:$Z$4,'⚙ Dashboard Settings'!$M$12-6)="","no date",INDEX('🧪 Lab Results'!$G$4:$Z$4,'⚙ Dashboard Settings'!$M$12-6))) -> — | H64: =IF('⚙ Dashboard Settings'!$N$12=0,"—",INDEX('🧪 Lab Results'!$G13:$Z13,'⚙ Dashboard Settings'!$N$12-6)) -> — | I64: =IF(AND(ISNUMBER(F64),ISNUMBER(H64)),ROUND(F64-H64,3),"—") -> — | J64: =IF(NOT(ISNUMBER(I64)),"—",IF(H64=0,IF(I64=0,"● Stable",IF(I64>0,"▲ Rising","▼ Falling")),IF(ABS(I64)/ABS(H64)*100<'⚙ Dashboard Settings'!$I$8,"● Stable",IF(I64>0,"▲ Rising","▼ Falling")))) -> — | K64: =IF('🧪 Lab Results'!$D$13="","",'🧪 Lab Results'!$D$13) -> 3.5 – 5.0 | M64: =IF('🧪 Lab Results'!$E$13="","",'🧪 Lab Results'!$E$13) -> 3.5 – 5.0 | O64: =IF(OR('⚙ Dashboard Settings'!$M$12=0,NOT(ISNUMBER(F64))),"—",IF(AND(ISNUMBER('⚙ Dashboard Settings'!$D$12),F64<'⚙ Dashboard Settings'!$D$12),"▼ LOW",IF(AND(ISNUMBER('⚙ Dashboard Settings'!$E$12),F64>'⚙ Dashboard Settings'!$E$12),"▲ HIGH",IF(AND(NOT(ISNUMBER('⚙ Dashboard Settings'!$D$12)),NOT(ISNUMBER('⚙ Dashboard Settings'!$E$12))),"—","✔ In range")))) -> — | P64: =COUNT('🧪 Lab Results'!$G13:$Z13) -> 0 | Q64: =IF('🧪 Lab Results'!$F$13="","",'🧪 Lab Results'!$F$13) -> Monthly
B65: =TRIM('🧪 Lab Results'!$B$14) -> Sodium | E65: =IF('🧪 Lab Results'!$C$14="","",'🧪 Lab Results'!$C$14) -> mEq/L | F65: =IF('⚙ Dashboard Settings'!$M$13=0,"—",INDEX('🧪 Lab Results'!$G14:$Z14,'⚙ Dashboard Settings'!$M$13-6)) -> — | G65: =IF('⚙ Dashboard Settings'!$M$13=0,"—",IF(INDEX('🧪 Lab Results'!$G$4:$Z$4,'⚙ Dashboard Settings'!$M$13-6)="","no date",INDEX('🧪 Lab Results'!$G$4:$Z$4,'⚙ Dashboard Settings'!$M$13-6))) -> — | H65: =IF('⚙ Dashboard Settings'!$N$13=0,"—",INDEX('🧪 Lab Results'!$G14:$Z14,'⚙ Dashboard Settings'!$N$13-6)) -> — | I65: =IF(AND(ISNUMBER(F65),ISNUMBER(H65)),ROUND(F65-H65,3),"—") -> — | J65: =IF(NOT(ISNUMBER(I65)),"—",IF(H65=0,IF(I65=0,"● Stable",IF(I65>0,"▲ Rising","▼ Falling")),IF(ABS(I65)/ABS(H65)*100<'⚙ Dashboard Settings'!$I$8,"● Stable",IF(I65>0,"▲ Rising","▼ Falling")))) -> — | K65: =IF('🧪 Lab Results'!$D$14="","",'🧪 Lab Results'!$D$14) -> 135 – 145 | M65: =IF('🧪 Lab Results'!$E$14="","",'🧪 Lab Results'!$E$14) -> 135 – 145 | O65: =IF(OR('⚙ Dashboard Settings'!$M$13=0,NOT(ISNUMBER(F65))),"—",IF(AND(ISNUMBER('⚙ Dashboard Settings'!$D$13),F65<'⚙ Dashboard Settings'!$D$13),"▼ LOW",IF(AND(ISNUMBER('⚙ Dashboard Settings'!$E$13),F65>'⚙ Dashboard Settings'!$E$13),"▲ HIGH",IF(AND(NOT(ISNUMBER('⚙ Dashboard Settings'!$D$13)),NOT(ISNUMBER('⚙ Dashboard Settings'!$E$13))),"—","✔ In range")))) -> — | P65: =COUNT('🧪 Lab Results'!$G14:$Z14) -> 0 | Q65: =IF('🧪 Lab Results'!$F$14="","",'🧪 Lab Results'!$F$14) -> Monthly
B66: =TRIM('🧪 Lab Results'!$B$15) -> Serum Bicarbonate | E66: =IF('🧪 Lab Results'!$C$15="","",'🧪 Lab Results'!$C$15) -> mEq/L | F66: =IF('⚙ Dashboard Settings'!$M$14=0,"—",INDEX('🧪 Lab Results'!$G15:$Z15,'⚙ Dashboard Settings'!$M$14-6)) -> — | G66: =IF('⚙ Dashboard Settings'!$M$14=0,"—",IF(INDEX('🧪 Lab Results'!$G$4:$Z$4,'⚙ Dashboard Settings'!$M$14-6)="","no date",INDEX('🧪 Lab Results'!$G$4:$Z$4,'⚙ Dashboard Settings'!$M$14-6))) -> — | H66: =IF('⚙ Dashboard Settings'!$N$14=0,"—",INDEX('🧪 Lab Results'!$G15:$Z15,'⚙ Dashboard Settings'!$N$14-6)) -> — | I66: =IF(AND(ISNUMBER(F66),ISNUMBER(H66)),ROUND(F66-H66,3),"—") -> — | J66: =IF(NOT(ISNUMBER(I66)),"—",IF(H66=0,IF(I66=0,"● Stable",IF(I66>0,"▲ Rising","▼ Falling")),IF(ABS(I66)/ABS(H66)*100<'⚙ Dashboard Settings'!$I$8,"● Stable",IF(I66>0,"▲ Rising","▼ Falling")))) -> — | K66: =IF('🧪 Lab Results'!$D$15="","",'🧪 Lab Results'!$D$15) -> 22 – 29 | M66: =IF('🧪 Lab Results'!$E$15="","",'🧪 Lab Results'!$E$15) -> 22 – 29 | O66: =IF(OR('⚙ Dashboard Settings'!$M$14=0,NOT(ISNUMBER(F66))),"—",IF(AND(ISNUMBER('⚙ Dashboard Settings'!$D$14),F66<'⚙ Dashboard Settings'!$D$14),"▼ LOW",IF(AND(ISNUMBER('⚙ Dashboard Settings'!$E$14),F66>'⚙ Dashboard Settings'!$E$14),"▲ HIGH",IF(AND(NOT(ISNUMBER('⚙ Dashboard Settings'!$D$14)),NOT(ISNUMBER('⚙ Dashboard Settings'!$E$14))),"—","✔ In range")))) -> — | P66: =COUNT('🧪 Lab Results'!$G15:$Z15) -> 0 | Q66: =IF('🧪 Lab Results'!$F$15="","",'🧪 Lab Results'!$F$15) -> Monthly
B67: =TRIM('🧪 Lab Results'!$B$17) -> FBS (Fasting Sugar) | E67: =IF('🧪 Lab Results'!$C$17="","",'🧪 Lab Results'!$C$17) -> mg/dL | F67: =IF('⚙ Dashboard Settings'!$M$15=0,"—",INDEX('🧪 Lab Results'!$G17:$Z17,'⚙ Dashboard Settings'!$M$15-6)) -> — | G67: =IF('⚙ Dashboard Settings'!$M$15=0,"—",IF(INDEX('🧪 Lab Results'!$G$4:$Z$4,'⚙ Dashboard Settings'!$M$15-6)="","no date",INDEX('🧪 Lab Results'!$G$4:$Z$4,'⚙ Dashboard Settings'!$M$15-6))) -> — | H67: =IF('⚙ Dashboard Settings'!$N$15=0,"—",INDEX('🧪 Lab Results'!$G17:$Z17,'⚙ Dashboard Settings'!$N$15-6)) -> — | I67: =IF(AND(ISNUMBER(F67),ISNUMBER(H67)),ROUND(F67-H67,3),"—") -> — | J67: =IF(NOT(ISNUMBER(I67)),"—",IF(H67=0,IF(I67=0,"● Stable",IF(I67>0,"▲ Rising","▼ Falling")),IF(ABS(I67)/ABS(H67)*100<'⚙ Dashboard Settings'!$I$8,"● Stable",IF(I67>0,"▲ Rising","▼ Falling")))) -> — | K67: =IF('🧪 Lab Results'!$D$17="","",'🧪 Lab Results'!$D$17) -> 70 – 100 | M67: =IF('🧪 Lab Results'!$E$17="","",'🧪 Lab Results'!$E$17) -> 70 – 126 | O67: =IF(OR('⚙ Dashboard Settings'!$M$15=0,NOT(ISNUMBER(F67))),"—",IF(AND(ISNUMBER('⚙ Dashboard Settings'!$D$15),F67<'⚙ Dashboard Settings'!$D$15),"▼ LOW",IF(AND(ISNUMBER('⚙ Dashboard Settings'!$E$15),F67>'⚙ Dashboard Settings'!$E$15),"▲ HIGH",IF(AND(NOT(ISNUMBER('⚙ Dashboard Settings'!$D$15)),NOT(ISNUMBER('⚙ Dashboard Settings'!$E$15))),"—","✔ In range")))) -> — | P67: =COUNT('🧪 Lab Results'!$G17:$Z17) -> 0 | Q67: =IF('🧪 Lab Results'!$F$17="","",'🧪 Lab Results'!$F$17) -> Monthly
B68: =TRIM('🧪 Lab Results'!$B$18) -> PPBS (Post-meal) | E68: =IF('🧪 Lab Results'!$C$18="","",'🧪 Lab Results'!$C$18) -> mg/dL | F68: =IF('⚙ Dashboard Settings'!$M$16=0,"—",INDEX('🧪 Lab Results'!$G18:$Z18,'⚙ Dashboard Settings'!$M$16-6)) -> — | G68: =IF('⚙ Dashboard Settings'!$M$16=0,"—",IF(INDEX('🧪 Lab Results'!$G$4:$Z$4,'⚙ Dashboard Settings'!$M$16-6)="","no date",INDEX('🧪 Lab Results'!$G$4:$Z$4,'⚙ Dashboard Settings'!$M$16-6))) -> — | H68: =IF('⚙ Dashboard Settings'!$N$16=0,"—",INDEX('🧪 Lab Results'!$G18:$Z18,'⚙ Dashboard Settings'!$N$16-6)) -> — | I68: =IF(AND(ISNUMBER(F68),ISNUMBER(H68)),ROUND(F68-H68,3),"—") -> — | J68: =IF(NOT(ISNUMBER(I68)),"—",IF(H68=0,IF(I68=0,"● Stable",IF(I68>0,"▲ Rising","▼ Falling")),IF(ABS(I68)/ABS(H68)*100<'⚙ Dashboard Settings'!$I$8,"● Stable",IF(I68>0,"▲ Rising","▼ Falling")))) -> — | K68: =IF('🧪 Lab Results'!$D$18="","",'🧪 Lab Results'!$D$18) -> ≤ 140 | M68: =IF('🧪 Lab Results'!$E$18="","",'🧪 Lab Results'!$E$18) -> ≤ 180 | O68: =IF(OR('⚙ Dashboard Settings'!$M$16=0,NOT(ISNUMBER(F68))),"—",IF(AND(ISNUMBER('⚙ Dashboard Settings'!$D$16),F68<'⚙ Dashboard Settings'!$D$16),"▼ LOW",IF(AND(ISNUMBER('⚙ Dashboard Settings'!$E$16),F68>'⚙ Dashboard Settings'!$E$16),"▲ HIGH",IF(AND(NOT(ISNUMBER('⚙ Dashboard Settings'!$D$16)),NOT(ISNUMBER('⚙ Dashboard Settings'!$E$16))),"—","✔ In range")))) -> — | P68: =COUNT('🧪 Lab Results'!$G18:$Z18) -> 0 | Q68: =IF('🧪 Lab Results'!$F$18="","",'🧪 Lab Results'!$F$18) -> Monthly
B69: =TRIM('🧪 Lab Results'!$B$19) -> HbA1c | E69: =IF('🧪 Lab Results'!$C$19="","",'🧪 Lab Results'!$C$19) -> % | F69: =IF('⚙ Dashboard Settings'!$M$17=0,"—",INDEX('🧪 Lab Results'!$G19:$Z19,'⚙ Dashboard Settings'!$M$17-6)) -> — | G69: =IF('⚙ Dashboard Settings'!$M$17=0,"—",IF(INDEX('🧪 Lab Results'!$G$4:$Z$4,'⚙ Dashboard Settings'!$M$17-6)="","no date",INDEX('🧪 Lab Results'!$G$4:$Z$4,'⚙ Dashboard Settings'!$M$17-6))) -> — | H69: =IF('⚙ Dashboard Settings'!$N$17=0,"—",INDEX('🧪 Lab Results'!$G19:$Z19,'⚙ Dashboard Settings'!$N$17-6)) -> — | I69: =IF(AND(ISNUMBER(F69),ISNUMBER(H69)),ROUND(F69-H69,3),"—") -> — | J69: =IF(NOT(ISNUMBER(I69)),"—",IF(H69=0,IF(I69=0,"● Stable",IF(I69>0,"▲ Rising","▼ Falling")),IF(ABS(I69)/ABS(H69)*100<'⚙ Dashboard Settings'!$I$8,"● Stable",IF(I69>0,"▲ Rising","▼ Falling")))) -> — | K69: =IF('🧪 Lab Results'!$D$19="","",'🧪 Lab Results'!$D$19) -> ≤ 5.7 | M69: =IF('🧪 Lab Results'!$E$19="","",'🧪 Lab Results'!$E$19) -> ≤ 7.0 | O69: =IF(OR('⚙ Dashboard Settings'!$M$17=0,NOT(ISNUMBER(F69))),"—",IF(AND(ISNUMBER('⚙ Dashboard Settings'!$D$17),F69<'⚙ Dashboard Settings'!$D$17),"▼ LOW",IF(AND(ISNUMBER('⚙ Dashboard Settings'!$E$17),F69>'⚙ Dashboard Settings'!$E$17),"▲ HIGH",IF(AND(NOT(ISNUMBER('⚙ Dashboard Settings'!$D$17)),NOT(ISNUMBER('⚙ Dashboard Settings'!$E$17))),"—","✔ In range")))) -> — | P69: =COUNT('🧪 Lab Results'!$G19:$Z19) -> 0 | Q69: =IF('🧪 Lab Results'!$F$19="","",'🧪 Lab Results'!$F$19) -> 3-Monthly
B70: =TRIM('🧪 Lab Results'!$B$21) -> Haemoglobin | E70: =IF('🧪 Lab Results'!$C$21="","",'🧪 Lab Results'!$C$21) -> g/dL | F70: =IF('⚙ Dashboard Settings'!$M$18=0,"—",INDEX('🧪 Lab Results'!$G21:$Z21,'⚙ Dashboard Settings'!$M$18-6)) -> — | G70: =IF('⚙ Dashboard Settings'!$M$18=0,"—",IF(INDEX('🧪 Lab Results'!$G$4:$Z$4,'⚙ Dashboard Settings'!$M$18-6)="","no date",INDEX('🧪 Lab Results'!$G$4:$Z$4,'⚙ Dashboard Settings'!$M$18-6))) -> — | H70: =IF('⚙ Dashboard Settings'!$N$18=0,"—",INDEX('🧪 Lab Results'!$G21:$Z21,'⚙ Dashboard Settings'!$N$18-6)) -> — | I70: =IF(AND(ISNUMBER(F70),ISNUMBER(H70)),ROUND(F70-H70,3),"—") -> — | J70: =IF(NOT(ISNUMBER(I70)),"—",IF(H70=0,IF(I70=0,"● Stable",IF(I70>0,"▲ Rising","▼ Falling")),IF(ABS(I70)/ABS(H70)*100<'⚙ Dashboard Settings'!$I$8,"● Stable",IF(I70>0,"▲ Rising","▼ Falling")))) -> — | K70: =IF('🧪 Lab Results'!$D$21="","",'🧪 Lab Results'!$D$21) -> 12 – 17 | M70: =IF('🧪 Lab Results'!$E$21="","",'🧪 Lab Results'!$E$21) -> 11 – 14 | O70: =IF(OR('⚙ Dashboard Settings'!$M$18=0,NOT(ISNUMBER(F70))),"—",IF(AND(ISNUMBER('⚙ Dashboard Settings'!$D$18),F70<'⚙ Dashboard Settings'!$D$18),"▼ LOW",IF(AND(ISNUMBER('⚙ Dashboard Settings'!$E$18),F70>'⚙ Dashboard Settings'!$E$18),"▲ HIGH",IF(AND(NOT(ISNUMBER('⚙ Dashboard Settings'!$D$18)),NOT(ISNUMBER('⚙ Dashboard Settings'!$E$18))),"—","✔ In range")))) -> — | P70: =COUNT('🧪 Lab Results'!$G21:$Z21) -> 0 | Q70: =IF('🧪 Lab Results'!$F$21="","",'🧪 Lab Results'!$F$21) -> Monthly
B71: =TRIM('🧪 Lab Results'!$B$22) -> TLC (WBC) | E71: =IF('🧪 Lab Results'!$C$22="","",'🧪 Lab Results'!$C$22) -> ×10³/μL | F71: =IF('⚙ Dashboard Settings'!$M$19=0,"—",INDEX('🧪 Lab Results'!$G22:$Z22,'⚙ Dashboard Settings'!$M$19-6)) -> — | G71: =IF('⚙ Dashboard Settings'!$M$19=0,"—",IF(INDEX('🧪 Lab Results'!$G$4:$Z$4,'⚙ Dashboard Settings'!$M$19-6)="","no date",INDEX('🧪 Lab Results'!$G$4:$Z$4,'⚙ Dashboard Settings'!$M$19-6))) -> — | H71: =IF('⚙ Dashboard Settings'!$N$19=0,"—",INDEX('🧪 Lab Results'!$G22:$Z22,'⚙ Dashboard Settings'!$N$19-6)) -> — | I71: =IF(AND(ISNUMBER(F71),ISNUMBER(H71)),ROUND(F71-H71,3),"—") -> — | J71: =IF(NOT(ISNUMBER(I71)),"—",IF(H71=0,IF(I71=0,"● Stable",IF(I71>0,"▲ Rising","▼ Falling")),IF(ABS(I71)/ABS(H71)*100<'⚙ Dashboard Settings'!$I$8,"● Stable",IF(I71>0,"▲ Rising","▼ Falling")))) -> — | K71: =IF('🧪 Lab Results'!$D$22="","",'🧪 Lab Results'!$D$22) -> 4 – 11 | M71: =IF('🧪 Lab Results'!$E$22="","",'🧪 Lab Results'!$E$22) -> 4 – 10 | O71: =IF(OR('⚙ Dashboard Settings'!$M$19=0,NOT(ISNUMBER(F71))),"—",IF(AND(ISNUMBER('⚙ Dashboard Settings'!$D$19),F71<'⚙ Dashboard Settings'!$D$19),"▼ LOW",IF(AND(ISNUMBER('⚙ Dashboard Settings'!$E$19),F71>'⚙ Dashboard Settings'!$E$19),"▲ HIGH",IF(AND(NOT(ISNUMBER('⚙ Dashboard Settings'!$D$19)),NOT(ISNUMBER('⚙ Dashboard Settings'!$E$19))),"—","✔ In range")))) -> — | P71: =COUNT('🧪 Lab Results'!$G22:$Z22) -> 0 | Q71: =IF('🧪 Lab Results'!$F$22="","",'🧪 Lab Results'!$F$22) -> Monthly
B72: =TRIM('🧪 Lab Results'!$B$23) -> Platelets | E72: =IF('🧪 Lab Results'!$C$23="","",'🧪 Lab Results'!$C$23) -> ×10³/μL | F72: =IF('⚙ Dashboard Settings'!$M$20=0,"—",INDEX('🧪 Lab Results'!$G23:$Z23,'⚙ Dashboard Settings'!$M$20-6)) -> — | G72: =IF('⚙ Dashboard Settings'!$M$20=0,"—",IF(INDEX('🧪 Lab Results'!$G$4:$Z$4,'⚙ Dashboard Settings'!$M$20-6)="","no date",INDEX('🧪 Lab Results'!$G$4:$Z$4,'⚙ Dashboard Settings'!$M$20-6))) -> — | H72: =IF('⚙ Dashboard Settings'!$N$20=0,"—",INDEX('🧪 Lab Results'!$G23:$Z23,'⚙ Dashboard Settings'!$N$20-6)) -> — | I72: =IF(AND(ISNUMBER(F72),ISNUMBER(H72)),ROUND(F72-H72,3),"—") -> — | J72: =IF(NOT(ISNUMBER(I72)),"—",IF(H72=0,IF(I72=0,"● Stable",IF(I72>0,"▲ Rising","▼ Falling")),IF(ABS(I72)/ABS(H72)*100<'⚙ Dashboard Settings'!$I$8,"● Stable",IF(I72>0,"▲ Rising","▼ Falling")))) -> — | K72: =IF('🧪 Lab Results'!$D$23="","",'🧪 Lab Results'!$D$23) -> 150 – 400 | M72: =IF('🧪 Lab Results'!$E$23="","",'🧪 Lab Results'!$E$23) -> 150 – 350 | O72: =IF(OR('⚙ Dashboard Settings'!$M$20=0,NOT(ISNUMBER(F72))),"—",IF(AND(ISNUMBER('⚙ Dashboard Settings'!$D$20),F72<'⚙ Dashboard Settings'!$D$20),"▼ LOW",IF(AND(ISNUMBER('⚙ Dashboard Settings'!$E$20),F72>'⚙ Dashboard Settings'!$E$20),"▲ HIGH",IF(AND(NOT(ISNUMBER('⚙ Dashboard Settings'!$D$20)),NOT(ISNUMBER('⚙ Dashboard Settings'!$E$20))),"—","✔ In range")))) -> — | P72: =COUNT('🧪 Lab Results'!$G23:$Z23) -> 0 | Q72: =IF('🧪 Lab Results'!$F$23="","",'🧪 Lab Results'!$F$23) -> Monthly
B73: =TRIM('🧪 Lab Results'!$B$25) -> Serum Albumin | E73: =IF('🧪 Lab Results'!$C$25="","",'🧪 Lab Results'!$C$25) -> g/dL | F73: =IF('⚙ Dashboard Settings'!$M$21=0,"—",INDEX('🧪 Lab Results'!$G25:$Z25,'⚙ Dashboard Settings'!$M$21-6)) -> — | G73: =IF('⚙ Dashboard Settings'!$M$21=0,"—",IF(INDEX('🧪 Lab Results'!$G$4:$Z$4,'⚙ Dashboard Settings'!$M$21-6)="","no date",INDEX('🧪 Lab Results'!$G$4:$Z$4,'⚙ Dashboard Settings'!$M$21-6))) -> — | H73: =IF('⚙ Dashboard Settings'!$N$21=0,"—",INDEX('🧪 Lab Results'!$G25:$Z25,'⚙ Dashboard Settings'!$N$21-6)) -> — | I73: =IF(AND(ISNUMBER(F73),ISNUMBER(H73)),ROUND(F73-H73,3),"—") -> — | J73: =IF(NOT(ISNUMBER(I73)),"—",IF(H73=0,IF(I73=0,"● Stable",IF(I73>0,"▲ Rising","▼ Falling")),IF(ABS(I73)/ABS(H73)*100<'⚙ Dashboard Settings'!$I$8,"● Stable",IF(I73>0,"▲ Rising","▼ Falling")))) -> — | K73: =IF('🧪 Lab Results'!$D$25="","",'🧪 Lab Results'!$D$25) -> 3.5 – 5.0 | M73: =IF('🧪 Lab Results'!$E$25="","",'🧪 Lab Results'!$E$25) -> 3.5 – 5.0 | O73: =IF(OR('⚙ Dashboard Settings'!$M$21=0,NOT(ISNUMBER(F73))),"—",IF(AND(ISNUMBER('⚙ Dashboard Settings'!$D$21),F73<'⚙ Dashboard Settings'!$D$21),"▼ LOW",IF(AND(ISNUMBER('⚙ Dashboard Settings'!$E$21),F73>'⚙ Dashboard Settings'!$E$21),"▲ HIGH",IF(AND(NOT(ISNUMBER('⚙ Dashboard Settings'!$D$21)),NOT(ISNUMBER('⚙ Dashboard Settings'!$E$21))),"—","✔ In range")))) -> — | P73: =COUNT('🧪 Lab Results'!$G25:$Z25) -> 0 | Q73: =IF('🧪 Lab Results'!$F$25="","",'🧪 Lab Results'!$F$25) -> Monthly
B74: =TRIM('🧪 Lab Results'!$B$26) -> Total Bilirubin | E74: =IF('🧪 Lab Results'!$C$26="","",'🧪 Lab Results'!$C$26) -> mg/dL | F74: =IF('⚙ Dashboard Settings'!$M$22=0,"—",INDEX('🧪 Lab Results'!$G26:$Z26,'⚙ Dashboard Settings'!$M$22-6)) -> — | G74: =IF('⚙ Dashboard Settings'!$M$22=0,"—",IF(INDEX('🧪 Lab Results'!$G$4:$Z$4,'⚙ Dashboard Settings'!$M$22-6)="","no date",INDEX('🧪 Lab Results'!$G$4:$Z$4,'⚙ Dashboard Settings'!$M$22-6))) -> — | H74: =IF('⚙ Dashboard Settings'!$N$22=0,"—",INDEX('🧪 Lab Results'!$G26:$Z26,'⚙ Dashboard Settings'!$N$22-6)) -> — | I74: =IF(AND(ISNUMBER(F74),ISNUMBER(H74)),ROUND(F74-H74,3),"—") -> — | J74: =IF(NOT(ISNUMBER(I74)),"—",IF(H74=0,IF(I74=0,"● Stable",IF(I74>0,"▲ Rising","▼ Falling")),IF(ABS(I74)/ABS(H74)*100<'⚙ Dashboard Settings'!$I$8,"● Stable",IF(I74>0,"▲ Rising","▼ Falling")))) -> — | K74: =IF('🧪 Lab Results'!$D$26="","",'🧪 Lab Results'!$D$26) -> ≤ 1.2 | M74: =IF('🧪 Lab Results'!$E$26="","",'🧪 Lab Results'!$E$26) -> ≤ 1.2 | O74: =IF(OR('⚙ Dashboard Settings'!$M$22=0,NOT(ISNUMBER(F74))),"—",IF(AND(ISNUMBER('⚙ Dashboard Settings'!$D$22),F74<'⚙ Dashboard Settings'!$D$22),"▼ LOW",IF(AND(ISNUMBER('⚙ Dashboard Settings'!$E$22),F74>'⚙ Dashboard Settings'!$E$22),"▲ HIGH",IF(AND(NOT(ISNUMBER('⚙ Dashboard Settings'!$D$22)),NOT(ISNUMBER('⚙ Dashboard Settings'!$E$22))),"—","✔ In range")))) -> — | P74: =COUNT('🧪 Lab Results'!$G26:$Z26) -> 0 | Q74: =IF('🧪 Lab Results'!$F$26="","",'🧪 Lab Results'!$F$26) -> 3-Monthly
B75: =TRIM('🧪 Lab Results'!$B$27) -> SGOT / AST | E75: =IF('🧪 Lab Results'!$C$27="","",'🧪 Lab Results'!$C$27) -> U/L | F75: =IF('⚙ Dashboard Settings'!$M$23=0,"—",INDEX('🧪 Lab Results'!$G27:$Z27,'⚙ Dashboard Settings'!$M$23-6)) -> — | G75: =IF('⚙ Dashboard Settings'!$M$23=0,"—",IF(INDEX('🧪 Lab Results'!$G$4:$Z$4,'⚙ Dashboard Settings'!$M$23-6)="","no date",INDEX('🧪 Lab Results'!$G$4:$Z$4,'⚙ Dashboard Settings'!$M$23-6))) -> — | H75: =IF('⚙ Dashboard Settings'!$N$23=0,"—",INDEX('🧪 Lab Results'!$G27:$Z27,'⚙ Dashboard Settings'!$N$23-6)) -> — | I75: =IF(AND(ISNUMBER(F75),ISNUMBER(H75)),ROUND(F75-H75,3),"—") -> — | J75: =IF(NOT(ISNUMBER(I75)),"—",IF(H75=0,IF(I75=0,"● Stable",IF(I75>0,"▲ Rising","▼ Falling")),IF(ABS(I75)/ABS(H75)*100<'⚙ Dashboard Settings'!$I$8,"● Stable",IF(I75>0,"▲ Rising","▼ Falling")))) -> — | K75: =IF('🧪 Lab Results'!$D$27="","",'🧪 Lab Results'!$D$27) -> ≤ 40 | M75: =IF('🧪 Lab Results'!$E$27="","",'🧪 Lab Results'!$E$27) -> ≤ 40 | O75: =IF(OR('⚙ Dashboard Settings'!$M$23=0,NOT(ISNUMBER(F75))),"—",IF(AND(ISNUMBER('⚙ Dashboard Settings'!$D$23),F75<'⚙ Dashboard Settings'!$D$23),"▼ LOW",IF(AND(ISNUMBER('⚙ Dashboard Settings'!$E$23),F75>'⚙ Dashboard Settings'!$E$23),"▲ HIGH",IF(AND(NOT(ISNUMBER('⚙ Dashboard Settings'!$D$23)),NOT(ISNUMBER('⚙ Dashboard Settings'!$E$23))),"—","✔ In range")))) -> — | P75: =COUNT('🧪 Lab Results'!$G27:$Z27) -> 0 | Q75: =IF('🧪 Lab Results'!$F$27="","",'🧪 Lab Results'!$F$27) -> 3-Monthly
B76: =TRIM('🧪 Lab Results'!$B$28) -> SGPT / ALT | E76: =IF('🧪 Lab Results'!$C$28="","",'🧪 Lab Results'!$C$28) -> U/L | F76: =IF('⚙ Dashboard Settings'!$M$24=0,"—",INDEX('🧪 Lab Results'!$G28:$Z28,'⚙ Dashboard Settings'!$M$24-6)) -> — | G76: =IF('⚙ Dashboard Settings'!$M$24=0,"—",IF(INDEX('🧪 Lab Results'!$G$4:$Z$4,'⚙ Dashboard Settings'!$M$24-6)="","no date",INDEX('🧪 Lab Results'!$G$4:$Z$4,'⚙ Dashboard Settings'!$M$24-6))) -> — | H76: =IF('⚙ Dashboard Settings'!$N$24=0,"—",INDEX('🧪 Lab Results'!$G28:$Z28,'⚙ Dashboard Settings'!$N$24-6)) -> — | I76: =IF(AND(ISNUMBER(F76),ISNUMBER(H76)),ROUND(F76-H76,3),"—") -> — | J76: =IF(NOT(ISNUMBER(I76)),"—",IF(H76=0,IF(I76=0,"● Stable",IF(I76>0,"▲ Rising","▼ Falling")),IF(ABS(I76)/ABS(H76)*100<'⚙ Dashboard Settings'!$I$8,"● Stable",IF(I76>0,"▲ Rising","▼ Falling")))) -> — | K76: =IF('🧪 Lab Results'!$D$28="","",'🧪 Lab Results'!$D$28) -> ≤ 56 | M76: =IF('🧪 Lab Results'!$E$28="","",'🧪 Lab Results'!$E$28) -> ≤ 56 | O76: =IF(OR('⚙ Dashboard Settings'!$M$24=0,NOT(ISNUMBER(F76))),"—",IF(AND(ISNUMBER('⚙ Dashboard Settings'!$D$24),F76<'⚙ Dashboard Settings'!$D$24),"▼ LOW",IF(AND(ISNUMBER('⚙ Dashboard Settings'!$E$24),F76>'⚙ Dashboard Settings'!$E$24),"▲ HIGH",IF(AND(NOT(ISNUMBER('⚙ Dashboard Settings'!$D$24)),NOT(ISNUMBER('⚙ Dashboard Settings'!$E$24))),"—","✔ In range")))) -> — | P76: =COUNT('🧪 Lab Results'!$G28:$Z28) -> 0 | Q76: =IF('🧪 Lab Results'!$F$28="","",'🧪 Lab Results'!$F$28) -> 3-Monthly
B77: =TRIM('🧪 Lab Results'!$B$29) -> Lipid Profile (LDL) | E77: =IF('🧪 Lab Results'!$C$29="","",'🧪 Lab Results'!$C$29) -> mg/dL | F77: =IF('⚙ Dashboard Settings'!$M$25=0,"—",INDEX('🧪 Lab Results'!$G29:$Z29,'⚙ Dashboard Settings'!$M$25-6)) -> — | G77: =IF('⚙ Dashboard Settings'!$M$25=0,"—",IF(INDEX('🧪 Lab Results'!$G$4:$Z$4,'⚙ Dashboard Settings'!$M$25-6)="","no date",INDEX('🧪 Lab Results'!$G$4:$Z$4,'⚙ Dashboard Settings'!$M$25-6))) -> — | H77: =IF('⚙ Dashboard Settings'!$N$25=0,"—",INDEX('🧪 Lab Results'!$G29:$Z29,'⚙ Dashboard Settings'!$N$25-6)) -> — | I77: =IF(AND(ISNUMBER(F77),ISNUMBER(H77)),ROUND(F77-H77,3),"—") -> — | J77: =IF(NOT(ISNUMBER(I77)),"—",IF(H77=0,IF(I77=0,"● Stable",IF(I77>0,"▲ Rising","▼ Falling")),IF(ABS(I77)/ABS(H77)*100<'⚙ Dashboard Settings'!$I$8,"● Stable",IF(I77>0,"▲ Rising","▼ Falling")))) -> — | K77: =IF('🧪 Lab Results'!$D$29="","",'🧪 Lab Results'!$D$29) -> ≤ 100 | M77: =IF('🧪 Lab Results'!$E$29="","",'🧪 Lab Results'!$E$29) -> ≤ 100 | O77: =IF(OR('⚙ Dashboard Settings'!$M$25=0,NOT(ISNUMBER(F77))),"—",IF(AND(ISNUMBER('⚙ Dashboard Settings'!$D$25),F77<'⚙ Dashboard Settings'!$D$25),"▼ LOW",IF(AND(ISNUMBER('⚙ Dashboard Settings'!$E$25),F77>'⚙ Dashboard Settings'!$E$25),"▲ HIGH",IF(AND(NOT(ISNUMBER('⚙ Dashboard Settings'!$D$25)),NOT(ISNUMBER('⚙ Dashboard Settings'!$E$25))),"—","✔ In range")))) -> — | P77: =COUNT('🧪 Lab Results'!$G29:$Z29) -> 0 | Q77: =IF('🧪 Lab Results'!$F$29="","",'🧪 Lab Results'!$F$29) -> 3-Monthly
B78: =TRIM('🧪 Lab Results'!$B$31) -> Vitamin D (25-OH) | E78: =IF('🧪 Lab Results'!$C$31="","",'🧪 Lab Results'!$C$31) -> ng/mL | F78: =IF('⚙ Dashboard Settings'!$M$26=0,"—",INDEX('🧪 Lab Results'!$G31:$Z31,'⚙ Dashboard Settings'!$M$26-6)) -> — | G78: =IF('⚙ Dashboard Settings'!$M$26=0,"—",IF(INDEX('🧪 Lab Results'!$G$4:$Z$4,'⚙ Dashboard Settings'!$M$26-6)="","no date",INDEX('🧪 Lab Results'!$G$4:$Z$4,'⚙ Dashboard Settings'!$M$26-6))) -> — | H78: =IF('⚙ Dashboard Settings'!$N$26=0,"—",INDEX('🧪 Lab Results'!$G31:$Z31,'⚙ Dashboard Settings'!$N$26-6)) -> — | I78: =IF(AND(ISNUMBER(F78),ISNUMBER(H78)),ROUND(F78-H78,3),"—") -> — | J78: =IF(NOT(ISNUMBER(I78)),"—",IF(H78=0,IF(I78=0,"● Stable",IF(I78>0,"▲ Rising","▼ Falling")),IF(ABS(I78)/ABS(H78)*100<'⚙ Dashboard Settings'!$I$8,"● Stable",IF(I78>0,"▲ Rising","▼ Falling")))) -> — | K78: =IF('🧪 Lab Results'!$D$31="","",'🧪 Lab Results'!$D$31) -> 30 – 100 | M78: =IF('🧪 Lab Results'!$E$31="","",'🧪 Lab Results'!$E$31) -> 30 – 100 | O78: =IF(OR('⚙ Dashboard Settings'!$M$26=0,NOT(ISNUMBER(F78))),"—",IF(AND(ISNUMBER('⚙ Dashboard Settings'!$D$26),F78<'⚙ Dashboard Settings'!$D$26),"▼ LOW",IF(AND(ISNUMBER('⚙ Dashboard Settings'!$E$26),F78>'⚙ Dashboard Settings'!$E$26),"▲ HIGH",IF(AND(NOT(ISNUMBER('⚙ Dashboard Settings'!$D$26)),NOT(ISNUMBER('⚙ Dashboard Settings'!$E$26))),"—","✔ In range")))) -> — | P78: =COUNT('🧪 Lab Results'!$G31:$Z31) -> 0 | Q78: =IF('🧪 Lab Results'!$F$31="","",'🧪 Lab Results'!$F$31) -> 3-Monthly
B79: =TRIM('🧪 Lab Results'!$B$38) -> Urine PCR (UACR) | E79: =IF('🧪 Lab Results'!$C$38="","",'🧪 Lab Results'!$C$38) -> mg/g | F79: =IF('⚙ Dashboard Settings'!$M$27=0,"—",INDEX('🧪 Lab Results'!$G38:$Z38,'⚙ Dashboard Settings'!$M$27-6)) -> — | G79: =IF('⚙ Dashboard Settings'!$M$27=0,"—",IF(INDEX('🧪 Lab Results'!$G$4:$Z$4,'⚙ Dashboard Settings'!$M$27-6)="","no date",INDEX('🧪 Lab Results'!$G$4:$Z$4,'⚙ Dashboard Settings'!$M$27-6))) -> — | H79: =IF('⚙ Dashboard Settings'!$N$27=0,"—",INDEX('🧪 Lab Results'!$G38:$Z38,'⚙ Dashboard Settings'!$N$27-6)) -> — | I79: =IF(AND(ISNUMBER(F79),ISNUMBER(H79)),ROUND(F79-H79,3),"—") -> — | J79: =IF(NOT(ISNUMBER(I79)),"—",IF(H79=0,IF(I79=0,"● Stable",IF(I79>0,"▲ Rising","▼ Falling")),IF(ABS(I79)/ABS(H79)*100<'⚙ Dashboard Settings'!$I$8,"● Stable",IF(I79>0,"▲ Rising","▼ Falling")))) -> — | K79: =IF('🧪 Lab Results'!$D$38="","",'🧪 Lab Results'!$D$38) -> < 150 | M79: =IF('🧪 Lab Results'!$E$38="","",'🧪 Lab Results'!$E$38) -> < 300 | O79: =IF(OR('⚙ Dashboard Settings'!$M$27=0,NOT(ISNUMBER(F79))),"—",IF(AND(ISNUMBER('⚙ Dashboard Settings'!$D$27),F79<'⚙ Dashboard Settings'!$D$27),"▼ LOW",IF(AND(ISNUMBER('⚙ Dashboard Settings'!$E$27),F79>'⚙ Dashboard Settings'!$E$27),"▲ HIGH",IF(AND(NOT(ISNUMBER('⚙ Dashboard Settings'!$D$27)),NOT(ISNUMBER('⚙ Dashboard Settings'!$E$27))),"—","✔ In range")))) -> — | P79: =COUNT('🧪 Lab Results'!$G38:$Z38) -> 0 | Q79: =IF('🧪 Lab Results'!$F$38="","",'🧪 Lab Results'!$F$38) -> Monthly
B80: =TRIM('🧪 Lab Results'!$B$39) -> 24h Urine Protein | E80: =IF('🧪 Lab Results'!$C$39="","",'🧪 Lab Results'!$C$39) -> mg/24h | F80: =IF('⚙ Dashboard Settings'!$M$28=0,"—",INDEX('🧪 Lab Results'!$G39:$Z39,'⚙ Dashboard Settings'!$M$28-6)) -> — | G80: =IF('⚙ Dashboard Settings'!$M$28=0,"—",IF(INDEX('🧪 Lab Results'!$G$4:$Z$4,'⚙ Dashboard Settings'!$M$28-6)="","no date",INDEX('🧪 Lab Results'!$G$4:$Z$4,'⚙ Dashboard Settings'!$M$28-6))) -> — | H80: =IF('⚙ Dashboard Settings'!$N$28=0,"—",INDEX('🧪 Lab Results'!$G39:$Z39,'⚙ Dashboard Settings'!$N$28-6)) -> — | I80: =IF(AND(ISNUMBER(F80),ISNUMBER(H80)),ROUND(F80-H80,3),"—") -> — | J80: =IF(NOT(ISNUMBER(I80)),"—",IF(H80=0,IF(I80=0,"● Stable",IF(I80>0,"▲ Rising","▼ Falling")),IF(ABS(I80)/ABS(H80)*100<'⚙ Dashboard Settings'!$I$8,"● Stable",IF(I80>0,"▲ Rising","▼ Falling")))) -> — | K80: =IF('🧪 Lab Results'!$D$39="","",'🧪 Lab Results'!$D$39) -> < 150 | M80: =IF('🧪 Lab Results'!$E$39="","",'🧪 Lab Results'!$E$39) -> < 300 | O80: =IF(OR('⚙ Dashboard Settings'!$M$28=0,NOT(ISNUMBER(F80))),"—",IF(AND(ISNUMBER('⚙ Dashboard Settings'!$D$28),F80<'⚙ Dashboard Settings'!$D$28),"▼ LOW",IF(AND(ISNUMBER('⚙ Dashboard Settings'!$E$28),F80>'⚙ Dashboard Settings'!$E$28),"▲ HIGH",IF(AND(NOT(ISNUMBER('⚙ Dashboard Settings'!$D$28)),NOT(ISNUMBER('⚙ Dashboard Settings'!$E$28))),"—","✔ In range")))) -> — | P80: =COUNT('🧪 Lab Results'!$G39:$Z39) -> 0 | Q80: =IF('🧪 Lab Results'!$F$39="","",'🧪 Lab Results'!$F$39) -> If indicated
B81: Qualitative / PCR tests | E81: Unit | F81: Latest result | I81: Date | J81: Previous result | L81: Post-Tx target | O81: Status | P81: Frequency
B82: =TRIM('🧪 Lab Results'!$B$32) -> BKV PCR | E82: =IF('🧪 Lab Results'!$C$32="","",'🧪 Lab Results'!$C$32) -> copies/mL | F82: =IF('⚙ Dashboard Settings'!$M$29=0,"—",INDEX('🧪 Lab Results'!$G32:$Z32,'⚙ Dashboard Settings'!$M$29-6)) -> — | I82: =IF('⚙ Dashboard Settings'!$M$29=0,"—",IF(INDEX('🧪 Lab Results'!$G$4:$Z$4,'⚙ Dashboard Settings'!$M$29-6)="","no date",INDEX('🧪 Lab Results'!$G$4:$Z$4,'⚙ Dashboard Settings'!$M$29-6))) -> — | J82: =IF('⚙ Dashboard Settings'!$N$29=0,"—",INDEX('🧪 Lab Results'!$G32:$Z32,'⚙ Dashboard Settings'!$N$29-6)) -> — | L82: =IF('🧪 Lab Results'!$E$32="","",'🧪 Lab Results'!$E$32) -> < 10,000 | O82: =IF('⚙ Dashboard Settings'!$M$29=0,"—","Doctor review") -> — | P82: =IF('🧪 Lab Results'!$F$32="","",'🧪 Lab Results'!$F$32) -> Monthly × 9m then 3m
B83: =TRIM('🧪 Lab Results'!$B$33) -> CMV PCR | E83: =IF('🧪 Lab Results'!$C$33="","",'🧪 Lab Results'!$C$33) -> copies/mL | F83: =IF('⚙ Dashboard Settings'!$M$30=0,"—",INDEX('🧪 Lab Results'!$G33:$Z33,'⚙ Dashboard Settings'!$M$30-6)) -> — | I83: =IF('⚙ Dashboard Settings'!$M$30=0,"—",IF(INDEX('🧪 Lab Results'!$G$4:$Z$4,'⚙ Dashboard Settings'!$M$30-6)="","no date",INDEX('🧪 Lab Results'!$G$4:$Z$4,'⚙ Dashboard Settings'!$M$30-6))) -> — | J83: =IF('⚙ Dashboard Settings'!$N$30=0,"—",INDEX('🧪 Lab Results'!$G33:$Z33,'⚙ Dashboard Settings'!$N$30-6)) -> — | L83: =IF('🧪 Lab Results'!$E$33="","",'🧪 Lab Results'!$E$33) -> Undetectable | O83: =IF('⚙ Dashboard Settings'!$M$30=0,"—","Doctor review") -> — | P83: =IF('🧪 Lab Results'!$F$33="","",'🧪 Lab Results'!$F$33) -> Monthly × 6m
...

Sheet 🩺 Doctor Referral Report
B1: CLINICAL SUMMARY FOR TREATING NEPHROLOGIST — KIDNEY TRANSPLANT FOLLOW-UP
B2: Auto-populated from all sheets | Print & send to doctor before visit | Do not edit — data pulls automatically
B3: =IF(COUNTA('👤 Patient Info'!C4:C6,'👤 Patient Info'!F4)=0,"",'👤 Patient Info'!C4&" | "&'👤 Patient Info'!C5&" | Reg: "&'👤 Patient Info'!C6&" | Phone: "&'👤 Patient Info'!F4)
B4: PATIENT IDENTIFICATION
B5: Patient Name | C5: =IF('👤 Patient Info'!C8="","",'👤 Patient Info'!C8)
B6: Patient ID | C6: =IF('👤 Patient Info'!F8="","",'👤 Patient Info'!F8)
B7: Date of Birth | C7: =IF('👤 Patient Info'!C9="","",'👤 Patient Info'!C9)
B8: Gender | C8: =IF('👤 Patient Info'!C11="","",'👤 Patient Info'!C11)
B9: Blood Group | C9: =IF('👤 Patient Info'!C12="","",'👤 Patient Info'!C12)
B10: Transplant Date | C10: =IF('👤 Patient Info'!F11="","",'👤 Patient Info'!F11)
B11: Diagnosis | C11: =IF('👤 Patient Info'!F10="","",'👤 Patient Info'!F10)
B12: Comorbidities | C12: =IF('👤 Patient Info'!C18="","",'👤 Patient Info'!C18)
B13: VITALS SUMMARY — LAST 7 DAYS
B14: Parameter | C14: Min | D14: Max | E14: Average | F14: Unit | G14: Clinical Note
B15: BP Systolic (mmHg) | C15: {=IF(COUNTIFS('📅 Daily Vitals Log'!B:B,">="&(TODAY()-7),'📅 Daily Vitals Log'!C:C,"<>")=0,"—",MIN(IF(('📅 Daily Vitals Log'!$B$4:$B$500>=TODAY()-7)*('📅 Daily Vitals Log'!$C$4:$C$500<>""),'📅 Daily Vitals Log'!$C$4:$C$500)))} -> — | D15: {=IF(COUNTIFS('📅 Daily Vitals Log'!B:B,">="&(TODAY()-7),'📅 Daily Vitals Log'!C:C,"<>")=0,"—",MAX(IF(('📅 Daily Vitals Log'!$B$4:$B$500>=TODAY()-7)*('📅 Daily Vitals Log'!$C$4:$C$500<>""),'📅 Daily Vitals Log'!$C$4:$C$500)))} -> — | E15: =IFERROR(ROUND(AVERAGEIFS('📅 Daily Vitals Log'!C:C,'📅 Daily Vitals Log'!B:B,">="&(TODAY()-7)),1),"—") -> — | F15: mmHg | G15: Target: <130/80
B16: BP Diastolic (mmHg) | C16: {=IF(COUNTIFS('📅 Daily Vitals Log'!B:B,">="&(TODAY()-7),'📅 Daily Vitals Log'!D:D,"<>")=0,"—",MIN(IF(('📅 Daily Vitals Log'!$B$4:$B$500>=TODAY()-7)*('📅 Daily Vitals Log'!$D$4:$D$500<>""),'📅 Daily Vitals Log'!$D$4:$D$500)))} -> — | D16: {=IF(COUNTIFS('📅 Daily Vitals Log'!B:B,">="&(TODAY()-7),'📅 Daily Vitals Log'!D:D,"<>")=0,"—",MAX(IF(('📅 Daily Vitals Log'!$B$4:$B$500>=TODAY()-7)*('📅 Daily Vitals Log'!$D$4:$D$500<>""),'📅 Daily Vitals Log'!$D$4:$D$500)))} -> — | E16: =IFERROR(ROUND(AVERAGEIFS('📅 Daily Vitals Log'!D:D,'📅 Daily Vitals Log'!B:B,">="&(TODAY()-7)),1),"—") -> — | F16: mmHg | G16: Target: <80
B17: Pulse (bpm) | C17: {=IF(COUNTIFS('📅 Daily Vitals Log'!B:B,">="&(TODAY()-7),'📅 Daily Vitals Log'!E:E,"<>")=0,"—",MIN(IF(('📅 Daily Vitals Log'!$B$4:$B$500>=TODAY()-7)*('📅 Daily Vitals Log'!$E$4:$E$500<>""),'📅 Daily Vitals Log'!$E$4:$E$500)))} -> — | D17: {=IF(COUNTIFS('📅 Daily Vitals Log'!B:B,">="&(TODAY()-7),'📅 Daily Vitals Log'!E:E,"<>")=0,"—",MAX(IF(('📅 Daily Vitals Log'!$B$4:$B$500>=TODAY()-7)*('📅 Daily Vitals Log'!$E$4:$E$500<>""),'📅 Daily Vitals Log'!$E$4:$E$500)))} -> — | E17: =IFERROR(ROUND(AVERAGEIFS('📅 Daily Vitals Log'!E:E,'📅 Daily Vitals Log'!B:B,">="&(TODAY()-7)),1),"—") -> — | F17: bpm | G17: Normal: 60–100
B18: SpO₂ (%) | C18: {=IF(COUNTIFS('📅 Daily Vitals Log'!B:B,">="&(TODAY()-7),'📅 Daily Vitals Log'!F:F,"<>")=0,"—",MIN(IF(('📅 Daily Vitals Log'!$B$4:$B$500>=TODAY()-7)*('📅 Daily Vitals Log'!$F$4:$F$500<>""),'📅 Daily Vitals Log'!$F$4:$F$500)))} -> — | D18: {=IF(COUNTIFS('📅 Daily Vitals Log'!B:B,">="&(TODAY()-7),'📅 Daily Vitals Log'!F:F,"<>")=0,"—",MAX(IF(('📅 Daily Vitals Log'!$B$4:$B$500>=TODAY()-7)*('📅 Daily Vitals Log'!$F$4:$F$500<>""),'📅 Daily Vitals Log'!$F$4:$F$500)))} -> — | E18: =IFERROR(ROUND(AVERAGEIFS('📅 Daily Vitals Log'!F:F,'📅 Daily Vitals Log'!B:B,">="&(TODAY()-7)),1),"—") -> — | F18: % | G18: Alert if <94%
B19: Weight (kg) | C19: {=IF(COUNTIFS('📅 Daily Vitals Log'!B:B,">="&(TODAY()-7),'📅 Daily Vitals Log'!H:H,"<>")=0,"—",MIN(IF(('📅 Daily Vitals Log'!$B$4:$B$500>=TODAY()-7)*('📅 Daily Vitals Log'!$H$4:$H$500<>""),'📅 Daily Vitals Log'!$H$4:$H$500)))} -> — | D19: {=IF(COUNTIFS('📅 Daily Vitals Log'!B:B,">="&(TODAY()-7),'📅 Daily Vitals Log'!H:H,"<>")=0,"—",MAX(IF(('📅 Daily Vitals Log'!$B$4:$B$500>=TODAY()-7)*('📅 Daily Vitals Log'!$H$4:$H$500<>""),'📅 Daily Vitals Log'!$H$4:$H$500)))} -> — | E19: =IFERROR(ROUND(AVERAGEIFS('📅 Daily Vitals Log'!H:H,'📅 Daily Vitals Log'!B:B,">="&(TODAY()-7)),2),"—") -> — | F19: kg | G19: Gain >2 kg/week = alert
B20: Fluid Intake (mL/day) | C20: {=IF(COUNTIFS('📅 Daily Vitals Log'!B:B,">="&(TODAY()-7),'📅 Daily Vitals Log'!I:I,"<>")=0,"—",MIN(IF(('📅 Daily Vitals Log'!$B$4:$B$500>=TODAY()-7)*('📅 Daily Vitals Log'!$I$4:$I$500<>""),'📅 Daily Vitals Log'!$I$4:$I$500)))} -> — | D20: {=IF(COUNTIFS('📅 Daily Vitals Log'!B:B,">="&(TODAY()-7),'📅 Daily Vitals Log'!I:I,"<>")=0,"—",MAX(IF(('📅 Daily Vitals Log'!$B$4:$B$500>=TODAY()-7)*('📅 Daily Vitals Log'!$I$4:$I$500<>""),'📅 Daily Vitals Log'!$I$4:$I$500)))} -> — | E20: =IFERROR(ROUND(AVERAGEIFS('📅 Daily Vitals Log'!I:I,'📅 Daily Vitals Log'!B:B,">="&(TODAY()-7)),0),"—") -> — | F20: mL | G20: Target: ≥4000 mL/day
B21: Urine Output (mL/day) | C21: {=IF(COUNTIFS('📅 Daily Vitals Log'!B:B,">="&(TODAY()-7),'📅 Daily Vitals Log'!J:J,"<>")=0,"—",MIN(IF(('📅 Daily Vitals Log'!$B$4:$B$500>=TODAY()-7)*('📅 Daily Vitals Log'!$J$4:$J$500<>""),'📅 Daily Vitals Log'!$J$4:$J$500)))} -> — | D21: {=IF(COUNTIFS('📅 Daily Vitals Log'!B:B,">="&(TODAY()-7),'📅 Daily Vitals Log'!J:J,"<>")=0,"—",MAX(IF(('📅 Daily Vitals Log'!$B$4:$B$500>=TODAY()-7)*('📅 Daily Vitals Log'!$J$4:$J$500<>""),'📅 Daily Vitals Log'!$J$4:$J$500)))} -> — | E21: =IFERROR(ROUND(AVERAGEIFS('📅 Daily Vitals Log'!J:J,'📅 Daily Vitals Log'!B:B,">="&(TODAY()-7)),0),"—") -> — | F21: mL | G21: Target: ≥1000 mL/day
